<?xml version="1.0"?>
<sdf version="1.9">
  <model name="portamail_robot">
    
    <!-- Base Link -->
    <link name="base_link">
      <pose>0 0 0.1 0 0 0</pose>
      <inertial>
        <mass>26.99</mass>
        <inertia>
          <ixx>0.619</ixx>
          <ixy>0</ixy>
          <ixz>0.006</ixz>
          <iyy>0.668</iyy>
          <iyz>0</iyz>
          <izz>0.983</izz>
        </inertia>
      </inertial>
      <visual name="base_visual">
        <geometry>
          <box>
            <size>0.4 0.3 0.2</size>
          </box>
        </geometry>
        <material>
          <ambient>0.75 0.75 0.75 1</ambient>
          <diffuse>0.75 0.75 0.75 1</diffuse>
        </material>
      </visual>
      <collision name="base_collision">
        <geometry>
          <box>
            <size>0.4 0.3 0.2</size>
          </box>
        </geometry>
      </collision>
    </link>

    <!-- Left Wheel -->
    <link name="left_wheel">
      <pose relative_to="base_link">-0.207 0.244 -0.016 1.5708 0 0</pose>
      <inertial>
        <mass>0.589</mass>
        <inertia>
          <ixx>0.00113</ixx>
          <iyy>0.00113</iyy>
          <izz>0.00220</izz>
          <ixy>0</ixy>
          <ixz>0</ixz>
          <iyz>0</iyz>
        </inertia>
      </inertial>
      <visual name="left_wheel_visual">
        <geometry>
          <cylinder>
            <radius>0.0325</radius>
            <length>0.04</length>
          </cylinder>
        </geometry>
        <material>
          <ambient>0.2 0.2 0.2 1</ambient>
          <diffuse>0.2 0.2 0.2 1</diffuse>
        </material>
      </visual>
      <collision name="left_wheel_collision">
        <geometry>
          <cylinder>
            <radius>0.0325</radius>
            <length>0.04</length>
          </cylinder>
        </geometry>
        <surface>
          <friction>
            <ode>
              <mu>1.0</mu>
              <mu2>1.0</mu2>
            </ode>
          </friction>
        </surface>
      </collision>
    </link>

    <!-- Right Wheel -->
    <link name="right_wheel">
      <pose relative_to="base_link">-0.207 -0.254 -0.016 1.5708 0 0</pose>
      <inertial>
        <mass>0.589</mass>
        <inertia>
          <ixx>0.00113</ixx>
          <iyy>0.00113</iyy>
          <izz>0.00220</izz>
          <ixy>0</ixy>
          <ixz>0</ixz>
          <iyz>0</iyz>
        </inertia>
      </inertial>
      <visual name="right_wheel_visual">
        <geometry>
          <cylinder>
            <radius>0.0325</radius>
            <length>0.04</length>
          </cylinder>
        </geometry>
        <material>
          <ambient>0.2 0.2 0.2 1</ambient>
          <diffuse>0.2 0.2 0.2 1</diffuse>
        </material>
      </visual>
      <collision name="right_wheel_collision">
        <geometry>
          <cylinder>
            <radius>0.0325</radius>
            <length>0.04</length>
          </cylinder>
        </geometry>
        <surface>
          <friction>
            <ode>
              <mu>1.0</mu>
              <mu2>1.0</mu2>
            </ode>
          </friction>
        </surface>
      </collision>
    </link>

    <!-- Caster Wheel -->
    <link name="caster_wheel">
      <pose relative_to="base_link">0.250 0 -0.07 0 0 0</pose>
      <inertial>
        <mass>0.066</mass>
        <inertia>
          <ixx>0.00003</ixx>
          <iyy>0.00003</iyy>
          <izz>0.00004</izz>
          <ixy>0</ixy>
          <ixz>0</ixz>
          <iyz>0</iyz>
        </inertia>
      </inertial>
      <visual name="caster_visual">
        <geometry>
          <sphere>
            <radius>0.02</radius>
          </sphere>
        </geometry>
        <material>
          <ambient>0.5 0.5 0.5 1</ambient>
          <diffuse>0.5 0.5 0.5 1</diffuse>
        </material>
      </visual>
      <collision name="caster_collision">
        <geometry>
          <sphere>
            <radius>0.02</radius>
          </sphere>
        </geometry>
        <surface>
          <friction>
            <ode>
              <mu>0.0</mu>
              <mu2>0.0</mu2>
            </ode>
          </friction>
        </surface>
      </collision>
    </link>

    <!-- Laser Link -->
    <link name="laser">
      <pose relative_to="base_link">0.1 0 0.15 0 0 0</pose>
      <inertial>
        <mass>0.125</mass>
        <inertia>
          <ixx>0.001</ixx>
          <iyy>0.001</iyy>
          <izz>0.001</izz>
          <ixy>0</ixy>
          <ixz>0</ixz>
          <iyz>0</iyz>
        </inertia>
      </inertial>
      <visual name="laser_visual">
        <geometry>
          <cylinder>
            <radius>0.04</radius>
            <length>0.05</length>
          </cylinder>
        </geometry>
        <material>
          <ambient>0.8 0.2 0.2 1</ambient>
          <diffuse>0.8 0.2 0.2 1</diffuse>
        </material>
      </visual>
      <collision name="laser_collision">
        <geometry>
          <cylinder>
            <radius>0.04</radius>
            <length>0.05</length>
          </cylinder>
        </geometry>
      </collision>
      
      <!-- GPU Lidar Sensor -->
      <sensor name="rplidar_sensor" type="gpu_lidar">
        <topic>/scan</topic>
        <update_rate>10</update_rate>
        <lidar>
          <scan>
            <horizontal>
              <samples>360</samples>
              <resolution>1</resolution>
              <min_angle>-3.14159</min_angle>
              <max_angle>3.14159</max_angle>
            </horizontal>
          </scan>
          <range>
            <min>0.15</min>
            <max>12.0</max>
            <resolution>0.01</resolution>
          </range>
          <noise>
            <type>gaussian</type>
            <mean>0.0</mean>
            <stddev>0.01</stddev>
          </noise>
        </lidar>
        <always_on>1</always_on>
        <visualize>true</visualize>
      </sensor>
    </link>

    <!-- Joints -->
    <joint name="left_wheel_joint" type="revolute">
      <parent>base_link</parent>
      <child>left_wheel</child>
      <axis>
        <xyz>0 0 1</xyz>
        <limit>
          <lower>-1e16</lower>
          <upper>1e16</upper>
        </limit>
      </axis>
    </joint>

    <joint name="right_wheel_joint" type="revolute">
      <parent>base_link</parent>
      <child>right_wheel</child>
      <axis>
        <xyz>0 0 1</xyz>
        <limit>
          <lower>-1e16</lower>
          <upper>1e16</upper>
        </limit>
      </axis>
    </joint>

    <joint name="caster_joint" type="fixed">
      <parent>base_link</parent>
      <child>caster_wheel</child>
    </joint>

    <joint name="laser_joint" type="fixed">
      <parent>base_link</parent>
      <child>laser</child>
    </joint>

    <!-- Differential Drive Plugin -->
    <plugin filename="gz-sim-diff-drive-system" name="gz::sim::systems::DiffDrive">
      <left_joint>left_wheel_joint</left_joint>
      <right_joint>right_wheel_joint</right_joint>
      <wheel_separation>0.498</wheel_separation>
      <wheel_radius>0.0325</wheel_radius>
      <odom_publish_frequency>50</odom_publish_frequency>
      <max_linear_acceleration>1.0</max_linear_acceleration>
      <max_angular_acceleration>2.0</max_angular_acceleration>
      <max_linear_velocity>0.89</max_linear_velocity>
      <max_angular_velocity>1.0</max_angular_velocity>
      <min_linear_velocity>-0.89</min_linear_velocity>
      <min_angular_velocity>-1.0</min_angular_velocity>
      <topic>/cmd_vel</topic>
      <odom_topic>/odom</odom_topic>
      <tf_topic>/tf</tf_topic>
      <frame_id>odom</frame_id>
      <child_frame_id>base_link</child_frame_id>
    </plugin>

    <!-- Pose Publisher (for TF) -->
    <plugin filename="gz-sim-pose-publisher-system" name="gz::sim::systems::PosePublisher">
      <publish_link_pose>true</publish_link_pose>
      <publish_sensor_pose>true</publish_sensor_pose>
      <publish_collision_pose>false</publish_collision_pose>
      <publish_visual_pose>false</publish_visual_pose>
      <publish_nested_model_pose>true</publish_nested_model_pose>
      <use_pose_vector_msg>true</use_pose_vector_msg>
      <update_frequency>50</update_frequency>
    </plugin>

  </model>
</sdf>
