<?xml version="1.0" encoding="utf-8"?>
<!-- This URDF was automatically created by SolidWorks to URDF Exporter! Originally created by Stephen Brawner (brawner@gmail.com) 
     Commit Version: 1.6.0-4-g7f85cfe  Build Version: 1.6.7995.38578
     For more information, please see http://wiki.ros.org/sw_urdf_exporter -->
<robot
  name="portamail_navigator">
  <link
    name="base_link">
    <inertial>
      <origin
        xyz="0.0063630754897825 -5.21295585675999E-05 0.227333133323625"
        rpy="0 0 0" />
      <mass
        value="26.9888276340048" />
      <inertia
        ixx="0.619289783520866"
        ixy="-8.46743686350242E-06"
        ixz="0.00620469301165874"
        iyy="0.668317680969144"
        iyz="-3.8099314253087E-05"
        izz="0.98303158566789" />
    </inertial>
    <visual>
      <origin
        xyz="0 0 0"
        rpy="0 0 0" />
      <geometry>
        <mesh
          filename="package://portamail_navigator/meshes/base_link.STL" />
      </geometry>
      <material
        name="">
        <color
          rgba="0.749019607843137 0.749019607843137 0.749019607843137 1" />
      </material>
    </visual>
    <collision>
      <origin
        xyz="0 0 0"
        rpy="0 0 0" />
      <geometry>
        <mesh
          filename="package://portamail_navigator/meshes/base_link.STL" />
      </geometry>
    </collision>
  </link>
  <link
    name="left_wheel">
    <inertial>
      <origin
        xyz="-5.00000000008827E-06 -0.000622719000890976 0.00272000000000006"
        rpy="0 0 0" />
      <mass
        value="0.588934998326518" />
      <inertia
        ixx="0.00112906781404818"
        ixy="-1.46165672188879E-34"
        ixz="3.72586046656329E-18"
        iyy="0.00112906781404818"
        iyz="1.19226945933937E-20"
        izz="0.00219619666423353" />
    </inertial>
    <visual>
      <origin
        xyz="0 0 0"
        rpy="0 0 0" />
      <geometry>
        <mesh
          filename="package://portamail_navigator/meshes/left_wheel.STL" />
      </geometry>
      <material
        name="">
        <color
          rgba="0.250980392156863 0.250980392156863 0.250980392156863 1" />
      </material>
    </visual>
    <collision>
      <origin
        xyz="0 0 0"
        rpy="0 0 0" />
      <geometry>
        <mesh
          filename="package://portamail_navigator/meshes/left_wheel.STL" />
      </geometry>
    </collision>
  </link>
  <joint
    name="left_wheel_joint"
    type="continuous">
    <origin
      xyz="-0.20717 0.24396 0.08439"
      rpy="1.5708 0 0" />
    <parent
      link="base_link" />
    <child
      link="left_wheel" />
    <axis
      xyz="0 0 1" />
  </joint>
  <link
    name="right_wheel">
    <inertial>
      <origin
        xyz="-5.00000000092093E-06 -0.000309216983811395 -0.248563206918676"
        rpy="0 0 0" />
      <mass
        value="1.17786999665304" />
      <inertia
        ixx="0.00225813562809636"
        ixy="-3.2240422475964E-33"
        ixz="6.35641910110874E-18"
        iyy="0.00225813562809636"
        iyz="-1.04456085598386E-18"
        izz="0.00439239332846706" />
    </inertial>
    <visual>
      <origin
        xyz="0 0 0"
        rpy="0 0 0" />
      <geometry>
        <mesh
          filename="package://portamail_navigator/meshes/right_wheel.STL" />
      </geometry>
      <material
        name="">
        <color
          rgba="0.250980392156863 0.250980392156863 0.250980392156863 1" />
      </material>
    </visual>
    <collision>
      <origin
        xyz="0 0 0"
        rpy="0 0 0" />
      <geometry>
        <mesh
          filename="package://portamail_navigator/meshes/right_wheel.STL" />
      </geometry>
    </collision>
  </link>
  <joint
    name="right_wheel_joint"
    type="continuous">
    <origin
      xyz="-0.20717 -0.25408 0.084386"
      rpy="1.5708 0 0" />
    <parent
      link="base_link" />
    <child
      link="right_wheel" />
    <axis
      xyz="0 0 -1" />
  </joint>
  <link
    name="caster_swivel">
    <inertial>
      <origin
        xyz="-0.010025817396546 -0.000341002844053785 -0.0141426235576368"
        rpy="0 0 0" />
      <mass
        value="0.0207150422696725" />
      <inertia
        ixx="1.66647080870315E-05"
        ixy="-1.61273485125663E-07"
        ixz="-3.37716878778582E-06"
        iyy="1.41653051172085E-05"
        iyz="-3.8830017129783E-08"
        izz="1.66086319394758E-05" />
    </inertial>
    <visual>
      <origin
        xyz="0 0 0"
        rpy="0 0 0" />
      <geometry>
        <mesh
          filename="package://portamail_navigator/meshes/caster_swivel.STL" />
      </geometry>
      <material
        name="">
        <color
          rgba="0.792156862745098 0.819607843137255 0.933333333333333 1" />
      </material>
    </visual>
    <collision>
      <origin
        xyz="0 0 0"
        rpy="0 0 0" />
      <geometry>
        <mesh
          filename="package://portamail_navigator/meshes/caster_swivel.STL" />
      </geometry>
    </collision>
  </link>
  <joint
    name="caster_swivel_joint"
    type="continuous">
    <origin
      xyz="0.25024 -6.9235E-05 0.073856"
      rpy="0 0 0" />
    <parent
      link="base_link" />
    <child
      link="caster_swivel" />
    <axis
      xyz="0 0 -1" />
  </joint>
  <link
    name="caster_wheel">
    <inertial>
      <origin
        xyz="0 0 6.93889390390723E-18"
        rpy="0 0 0" />
      <mass
        value="0.0661095439760222" />
      <inertia
        ixx="2.65274021094605E-05"
        ixy="-8.53413928790277E-22"
        ixz="1.19173199824834E-19"
        iyy="2.65274021094605E-05"
        iyz="5.62680425214823E-22"
        izz="4.2998993312912E-05" />
    </inertial>
    <visual>
      <origin
        xyz="0 0 0"
        rpy="0 0 0" />
      <geometry>
        <mesh
          filename="package://portamail_navigator/meshes/caster_wheel.STL" />
      </geometry>
      <material
        name="">
        <color
          rgba="0.792156862745098 0.819607843137255 0.933333333333333 1" />
      </material>
    </visual>
    <collision>
      <origin
        xyz="0 0 0"
        rpy="0 0 0" />
      <geometry>
        <mesh
          filename="package://portamail_navigator/meshes/caster_wheel.STL" />
      </geometry>
    </collision>
  </link>
  <joint
    name="caster_wheel_joint"
    type="continuous">
    <origin
      xyz="-0.0294640000000008 0 -0.0466424325660239"
      rpy="1.5707963267949 0 0" />
    <parent
      link="caster_swivel" />
    <child
      link="caster_wheel" />
    <axis
      xyz="0 0 -1" />
  </joint>
</robot>