<?xml version="1.0"?>
<robot name="portamail_robot" xmlns:xacro="http://www.ros.org/wiki/xacro">

  <!-- Base Link -->
  <link name="base_link">
    <inertial>
      <mass value="26.99"/>
      <origin xyz="0 0 0.1"/>
      <inertia ixx="0.619" ixy="0" ixz="0.006" iyy="0.668" iyz="0" izz="0.983"/>
    </inertial>
    <visual>
      <origin xyz="0 0 0.1" rpy="0 0 0"/>
      <geometry>
        <box size="0.4 0.3 0.2"/>
      </geometry>
      <material name="gray">
        <color rgba="0.75 0.75 0.75 1"/>
      </material>
    </visual>
    <collision>
      <origin xyz="0 0 0.1" rpy="0 0 0"/>
      <geometry>
        <box size="0.4 0.3 0.2"/>
      </geometry>
    </collision>
  </link>

  <!-- Left Wheel -->
  <link name="left_wheel">
    <inertial>
      <mass value="0.589"/>
      <inertia ixx="0.00113" ixy="0" ixz="0" iyy="0.00113" iyz="0" izz="0.00220"/>
    </inertial>
    <visual>
      <origin xyz="0 0 0" rpy="1.5708 0 0"/>
      <geometry>
        <cylinder radius="0.0325" length="0.04"/>
      </geometry>
      <material name="black">
        <color rgba="0.2 0.2 0.2 1"/>
      </material>
    </visual>
    <collision>
      <origin xyz="0 0 0" rpy="1.5708 0 0"/>
      <geometry>
        <cylinder radius="0.0325" length="0.04"/>
      </geometry>
    </collision>
  </link>

  <joint name="left_wheel_joint" type="continuous">
    <parent link="base_link"/>
    <child link="left_wheel"/>
    <origin xyz="-0.10 0.17 0.0325" rpy="0 0 0"/>
    <axis xyz="0 1 0"/>
  </joint>

  <!-- Right Wheel -->
  <link name="right_wheel">
    <inertial>
      <mass value="0.589"/>
      <inertia ixx="0.00113" ixy="0" ixz="0" iyy="0.00113" iyz="0" izz="0.00220"/>
    </inertial>
    <visual>
      <origin xyz="0 0 0" rpy="1.5708 0 0"/>
      <geometry>
        <cylinder radius="0.0325" length="0.04"/>
      </geometry>
      <material name="black">
        <color rgba="0.2 0.2 0.2 1"/>
      </material>
    </visual>
    <collision>
      <origin xyz="0 0 0" rpy="1.5708 0 0"/>
      <geometry>
        <cylinder radius="0.0325" length="0.04"/>
      </geometry>
    </collision>
  </link>

  <joint name="right_wheel_joint" type="continuous">
    <parent link="base_link"/>
    <child link="right_wheel"/>
    <origin xyz="-0.10 -0.17 0.0325" rpy="0 0 0"/>
    <axis xyz="0 1 0"/>
  </joint>

  <!-- Caster Wheel -->
  <link name="caster_wheel">
    <inertial>
      <mass value="0.066"/>
      <inertia ixx="0.00003" ixy="0" ixz="0" iyy="0.00003" iyz="0" izz="0.00004"/>
    </inertial>
    <visual>
      <geometry>
        <sphere radius="0.0325"/>
      </geometry>
      <material name="gray">
        <color rgba="0.5 0.5 0.5 1"/>
      </material>
    </visual>
    <collision>
      <geometry>
        <sphere radius="0.0325"/>
      </geometry>
    </collision>
  </link>

  <joint name="caster_joint" type="fixed">
    <parent link="base_link"/>
    <child link="caster_wheel"/>
    <origin xyz="0.15 0 0.0325" rpy="0 0 0"/>
  </joint>

  <!-- Laser Scanner -->
  <link name="laser">
    <inertial>
      <mass value="0.125"/>
      <inertia ixx="0.001" ixy="0" ixz="0" iyy="0.001" iyz="0" izz="0.001"/>
    </inertial>
    <visual>
      <geometry>
        <cylinder radius="0.04" length="0.05"/>
      </geometry>
      <material name="red">
        <color rgba="0.8 0.2 0.2 1"/>
      </material>
    </visual>
    <collision>
      <geometry>
        <cylinder radius="0.04" length="0.05"/>
      </geometry>
    </collision>
  </link>

  <joint name="laser_joint" type="fixed">
    <parent link="base_link"/>
    <child link="laser"/>
    <origin xyz="0.1 0 0.25" rpy="0 0 0"/>
  </joint>

  <!-- ============================================ -->
  <!-- GAZEBO CLASSIC PLUGINS -->
  <!-- ============================================ -->

  <!-- Differential Drive Controller -->
  <gazebo>
    <plugin name="differential_drive_controller" filename="libgazebo_ros_diff_drive.so">
      <update_rate>50</update_rate>
      <left_joint>left_wheel_joint</left_joint>
      <right_joint>right_wheel_joint</right_joint>
      <wheel_separation>0.34</wheel_separation>
      <wheel_diameter>0.065</wheel_diameter>
      <max_wheel_torque>20</max_wheel_torque>
      <max_wheel_acceleration>1.0</max_wheel_acceleration>
      <command_topic>cmd_vel</command_topic>
      <publish_odom>true</publish_odom>
      <publish_odom_tf>true</publish_odom_tf>
      <publish_wheel_tf>false</publish_wheel_tf>
      <odometry_topic>odom</odometry_topic>
      <odometry_frame>odom</odometry_frame>
      <robot_base_frame>base_link</robot_base_frame>
    </plugin>
  </gazebo>

  <!-- Lidar Sensor -->
  <gazebo reference="laser">
    <sensor type="ray" name="rplidar_sensor">
      <pose>0 0 0 0 0 0</pose>
      <visualize>true</visualize>
      <update_rate>10</update_rate>
      <ray>
        <scan>
          <horizontal>
            <samples>360</samples>
            <resolution>1</resolution>
            <min_angle>-3.14159</min_angle>
            <max_angle>3.14159</max_angle>
          </horizontal>
        </scan>
        <range>
          <min>0.15</min>
          <max>12.0</max>
          <resolution>0.01</resolution>
        </range>
        <noise>
          <type>gaussian</type>
          <mean>0.0</mean>
          <stddev>0.01</stddev>
        </noise>
      </ray>
      <plugin name="gazebo_ros_laser" filename="libgazebo_ros_ray_sensor.so">
        <ros>
          <remapping>~/out:=scan</remapping>
        </ros>
        <output_type>sensor_msgs/LaserScan</output_type>
        <frame_name>laser</frame_name>
      </plugin>
    </sensor>
  </gazebo>

  <!-- Material Properties -->
  <gazebo reference="base_link">
    <material>Gazebo/Grey</material>
  </gazebo>

  <gazebo reference="left_wheel">
    <material>Gazebo/Black</material>
    <mu1>1.0</mu1>
    <mu2>1.0</mu2>
    <kp>1000000.0</kp>
    <kd>100.0</kd>
  </gazebo>

  <gazebo reference="right_wheel">
    <material>Gazebo/Black</material>
    <mu1>1.0</mu1>
    <mu2>1.0</mu2>
    <kp>1000000.0</kp>
    <kd>100.0</kd>
  </gazebo>

  <gazebo reference="caster_wheel">
    <material>Gazebo/Grey</material>
    <mu1>0.0</mu1>
    <mu2>0.0</mu2>
  </gazebo>

  <gazebo reference="laser">
    <material>Gazebo/Red</material>
  </gazebo>

</robot>
